ERROR:django.request:Internal Server Error: /
Traceback (most recent call last):
  File "/home/deeplearning/djangogirls/myvenv/lib/python3.5/site-packages/django/core/handlers/exception.py", line 41, in inner
    response = get_response(request)
  File "/home/deeplearning/djangogirls/myvenv/lib/python3.5/site-packages/django/core/handlers/base.py", line 187, in _get_response
    response = self.process_exception_by_middleware(e, request)
  File "/home/deeplearning/djangogirls/myvenv/lib/python3.5/site-packages/django/core/handlers/base.py", line 185, in _get_response
    response = wrapped_callback(request, *callback_args, **callback_kwargs)
  File "/home/deeplearning/djangogirls/blog/views.py", line 12, in post_list
    posts = PostInstabotDjangoModel.objects.all()
AttributeError: type object 'PostInstabotDjangoModel' has no attribute 'objects'
WARNING:django.request:Not Found: /favicon.ico
ERROR:django.request:Internal Server Error: /admin/blog/instabotdjangomodel/add/
Traceback (most recent call last):
  File "/home/deeplearning/djangogirls/myvenv/lib/python3.5/site-packages/django/core/handlers/exception.py", line 41, in inner
    response = get_response(request)
  File "/home/deeplearning/djangogirls/myvenv/lib/python3.5/site-packages/django/core/handlers/base.py", line 187, in _get_response
    response = self.process_exception_by_middleware(e, request)
  File "/home/deeplearning/djangogirls/myvenv/lib/python3.5/site-packages/django/core/handlers/base.py", line 185, in _get_response
    response = wrapped_callback(request, *callback_args, **callback_kwargs)
  File "/home/deeplearning/djangogirls/myvenv/lib/python3.5/site-packages/django/contrib/admin/options.py", line 551, in wrapper
    return self.admin_site.admin_view(view)(*args, **kwargs)
  File "/home/deeplearning/djangogirls/myvenv/lib/python3.5/site-packages/django/utils/decorators.py", line 149, in _wrapped_view
    response = view_func(request, *args, **kwargs)
  File "/home/deeplearning/djangogirls/myvenv/lib/python3.5/site-packages/django/views/decorators/cache.py", line 57, in _wrapped_view_func
    response = view_func(request, *args, **kwargs)
  File "/home/deeplearning/djangogirls/myvenv/lib/python3.5/site-packages/django/contrib/admin/sites.py", line 224, in inner
    return view(request, *args, **kwargs)
  File "/home/deeplearning/djangogirls/myvenv/lib/python3.5/site-packages/django/contrib/admin/options.py", line 1508, in add_view
    return self.changeform_view(request, None, form_url, extra_context)
  File "/home/deeplearning/djangogirls/myvenv/lib/python3.5/site-packages/django/utils/decorators.py", line 67, in _wrapper
    return bound_func(*args, **kwargs)
  File "/home/deeplearning/djangogirls/myvenv/lib/python3.5/site-packages/django/utils/decorators.py", line 149, in _wrapped_view
    response = view_func(request, *args, **kwargs)
  File "/home/deeplearning/djangogirls/myvenv/lib/python3.5/site-packages/django/utils/decorators.py", line 63, in bound_func
    return func.__get__(self, type(self))(*args2, **kwargs2)
  File "/home/deeplearning/djangogirls/myvenv/lib/python3.5/site-packages/django/contrib/admin/options.py", line 1408, in changeform_view
    return self._changeform_view(request, object_id, form_url, extra_context)
  File "/home/deeplearning/djangogirls/myvenv/lib/python3.5/site-packages/django/contrib/admin/options.py", line 1448, in _changeform_view
    self.save_model(request, new_object, form, not add)
  File "/home/deeplearning/djangogirls/myvenv/lib/python3.5/site-packages/django/contrib/admin/options.py", line 979, in save_model
    obj.save()
  File "/home/deeplearning/djangogirls/blog/models.py", line 93, in save
    unfollow_whitelist=['example_user_1', 'example_user_2'])
  File "/home/deeplearning/djangogirls/blog/src/instabot.py", line 233, in __init__
    signal.signal(signal.SIGTERM, self.cleanup)
  File "/usr/lib/python3.5/signal.py", line 47, in signal
    handler = _signal.signal(_enum_to_int(signalnum), _enum_to_int(handler))
ValueError: signal only works in main thread
ERROR:django.request:Internal Server Error: /admin/blog/instabotdjangomodel/add/
Traceback (most recent call last):
  File "/home/deeplearning/djangogirls/myvenv/lib/python3.5/site-packages/django/db/backends/utils.py", line 64, in execute
    return self.cursor.execute(sql, params)
  File "/home/deeplearning/djangogirls/myvenv/lib/python3.5/site-packages/django/db/backends/sqlite3/base.py", line 328, in execute
    return Database.Cursor.execute(self, query, params)
sqlite3.OperationalError: no such table: blog_instabotdjangomodel

The above exception was the direct cause of the following exception:

Traceback (most recent call last):
  File "/home/deeplearning/djangogirls/myvenv/lib/python3.5/site-packages/django/core/handlers/exception.py", line 41, in inner
    response = get_response(request)
  File "/home/deeplearning/djangogirls/myvenv/lib/python3.5/site-packages/django/core/handlers/base.py", line 187, in _get_response
    response = self.process_exception_by_middleware(e, request)
  File "/home/deeplearning/djangogirls/myvenv/lib/python3.5/site-packages/django/core/handlers/base.py", line 185, in _get_response
    response = wrapped_callback(request, *callback_args, **callback_kwargs)
  File "/home/deeplearning/djangogirls/myvenv/lib/python3.5/site-packages/django/contrib/admin/options.py", line 551, in wrapper
    return self.admin_site.admin_view(view)(*args, **kwargs)
  File "/home/deeplearning/djangogirls/myvenv/lib/python3.5/site-packages/django/utils/decorators.py", line 149, in _wrapped_view
    response = view_func(request, *args, **kwargs)
  File "/home/deeplearning/djangogirls/myvenv/lib/python3.5/site-packages/django/views/decorators/cache.py", line 57, in _wrapped_view_func
    response = view_func(request, *args, **kwargs)
  File "/home/deeplearning/djangogirls/myvenv/lib/python3.5/site-packages/django/contrib/admin/sites.py", line 224, in inner
    return view(request, *args, **kwargs)
  File "/home/deeplearning/djangogirls/myvenv/lib/python3.5/site-packages/django/contrib/admin/options.py", line 1508, in add_view
    return self.changeform_view(request, None, form_url, extra_context)
  File "/home/deeplearning/djangogirls/myvenv/lib/python3.5/site-packages/django/utils/decorators.py", line 67, in _wrapper
    return bound_func(*args, **kwargs)
  File "/home/deeplearning/djangogirls/myvenv/lib/python3.5/site-packages/django/utils/decorators.py", line 149, in _wrapped_view
    response = view_func(request, *args, **kwargs)
  File "/home/deeplearning/djangogirls/myvenv/lib/python3.5/site-packages/django/utils/decorators.py", line 63, in bound_func
    return func.__get__(self, type(self))(*args2, **kwargs2)
  File "/home/deeplearning/djangogirls/myvenv/lib/python3.5/site-packages/django/contrib/admin/options.py", line 1408, in changeform_view
    return self._changeform_view(request, object_id, form_url, extra_context)
  File "/home/deeplearning/djangogirls/myvenv/lib/python3.5/site-packages/django/contrib/admin/options.py", line 1448, in _changeform_view
    self.save_model(request, new_object, form, not add)
  File "/home/deeplearning/djangogirls/myvenv/lib/python3.5/site-packages/django/contrib/admin/options.py", line 979, in save_model
    obj.save()
  File "/home/deeplearning/djangogirls/myvenv/lib/python3.5/site-packages/django/db/models/base.py", line 808, in save
    force_update=force_update, update_fields=update_fields)
  File "/home/deeplearning/djangogirls/myvenv/lib/python3.5/site-packages/django/db/models/base.py", line 838, in save_base
    updated = self._save_table(raw, cls, force_insert, force_update, using, update_fields)
  File "/home/deeplearning/djangogirls/myvenv/lib/python3.5/site-packages/django/db/models/base.py", line 924, in _save_table
    result = self._do_insert(cls._base_manager, using, fields, update_pk, raw)
  File "/home/deeplearning/djangogirls/myvenv/lib/python3.5/site-packages/django/db/models/base.py", line 963, in _do_insert
    using=using, raw=raw)
  File "/home/deeplearning/djangogirls/myvenv/lib/python3.5/site-packages/django/db/models/manager.py", line 85, in manager_method
    return getattr(self.get_queryset(), name)(*args, **kwargs)
  File "/home/deeplearning/djangogirls/myvenv/lib/python3.5/site-packages/django/db/models/query.py", line 1076, in _insert
    return query.get_compiler(using=using).execute_sql(return_id)
  File "/home/deeplearning/djangogirls/myvenv/lib/python3.5/site-packages/django/db/models/sql/compiler.py", line 1112, in execute_sql
    cursor.execute(sql, params)
  File "/home/deeplearning/djangogirls/myvenv/lib/python3.5/site-packages/django/db/backends/utils.py", line 79, in execute
    return super(CursorDebugWrapper, self).execute(sql, params)
  File "/home/deeplearning/djangogirls/myvenv/lib/python3.5/site-packages/django/db/backends/utils.py", line 64, in execute
    return self.cursor.execute(sql, params)
  File "/home/deeplearning/djangogirls/myvenv/lib/python3.5/site-packages/django/db/utils.py", line 94, in __exit__
    six.reraise(dj_exc_type, dj_exc_value, traceback)
  File "/home/deeplearning/djangogirls/myvenv/lib/python3.5/site-packages/django/utils/six.py", line 685, in reraise
    raise value.with_traceback(tb)
  File "/home/deeplearning/djangogirls/myvenv/lib/python3.5/site-packages/django/db/backends/utils.py", line 64, in execute
    return self.cursor.execute(sql, params)
  File "/home/deeplearning/djangogirls/myvenv/lib/python3.5/site-packages/django/db/backends/sqlite3/base.py", line 328, in execute
    return Database.Cursor.execute(self, query, params)
django.db.utils.OperationalError: no such table: blog_instabotdjangomodel
ERROR:django.request:Internal Server Error: /admin/blog/instabotdjangomodel/add/
Traceback (most recent call last):
  File "/home/deeplearning/djangogirls/myvenv/lib/python3.5/site-packages/django/db/backends/utils.py", line 64, in execute
    return self.cursor.execute(sql, params)
  File "/home/deeplearning/djangogirls/myvenv/lib/python3.5/site-packages/django/db/backends/sqlite3/base.py", line 328, in execute
    return Database.Cursor.execute(self, query, params)
sqlite3.OperationalError: no such table: blog_instabotdjangomodel

The above exception was the direct cause of the following exception:

Traceback (most recent call last):
  File "/home/deeplearning/djangogirls/myvenv/lib/python3.5/site-packages/django/core/handlers/exception.py", line 41, in inner
    response = get_response(request)
  File "/home/deeplearning/djangogirls/myvenv/lib/python3.5/site-packages/django/core/handlers/base.py", line 187, in _get_response
    response = self.process_exception_by_middleware(e, request)
  File "/home/deeplearning/djangogirls/myvenv/lib/python3.5/site-packages/django/core/handlers/base.py", line 185, in _get_response
    response = wrapped_callback(request, *callback_args, **callback_kwargs)
  File "/home/deeplearning/djangogirls/myvenv/lib/python3.5/site-packages/django/contrib/admin/options.py", line 551, in wrapper
    return self.admin_site.admin_view(view)(*args, **kwargs)
  File "/home/deeplearning/djangogirls/myvenv/lib/python3.5/site-packages/django/utils/decorators.py", line 149, in _wrapped_view
    response = view_func(request, *args, **kwargs)
  File "/home/deeplearning/djangogirls/myvenv/lib/python3.5/site-packages/django/views/decorators/cache.py", line 57, in _wrapped_view_func
    response = view_func(request, *args, **kwargs)
  File "/home/deeplearning/djangogirls/myvenv/lib/python3.5/site-packages/django/contrib/admin/sites.py", line 224, in inner
    return view(request, *args, **kwargs)
  File "/home/deeplearning/djangogirls/myvenv/lib/python3.5/site-packages/django/contrib/admin/options.py", line 1508, in add_view
    return self.changeform_view(request, None, form_url, extra_context)
  File "/home/deeplearning/djangogirls/myvenv/lib/python3.5/site-packages/django/utils/decorators.py", line 67, in _wrapper
    return bound_func(*args, **kwargs)
  File "/home/deeplearning/djangogirls/myvenv/lib/python3.5/site-packages/django/utils/decorators.py", line 149, in _wrapped_view
    response = view_func(request, *args, **kwargs)
  File "/home/deeplearning/djangogirls/myvenv/lib/python3.5/site-packages/django/utils/decorators.py", line 63, in bound_func
    return func.__get__(self, type(self))(*args2, **kwargs2)
  File "/home/deeplearning/djangogirls/myvenv/lib/python3.5/site-packages/django/contrib/admin/options.py", line 1408, in changeform_view
    return self._changeform_view(request, object_id, form_url, extra_context)
  File "/home/deeplearning/djangogirls/myvenv/lib/python3.5/site-packages/django/contrib/admin/options.py", line 1448, in _changeform_view
    self.save_model(request, new_object, form, not add)
  File "/home/deeplearning/djangogirls/myvenv/lib/python3.5/site-packages/django/contrib/admin/options.py", line 979, in save_model
    obj.save()
  File "/home/deeplearning/djangogirls/myvenv/lib/python3.5/site-packages/django/db/models/base.py", line 808, in save
    force_update=force_update, update_fields=update_fields)
  File "/home/deeplearning/djangogirls/myvenv/lib/python3.5/site-packages/django/db/models/base.py", line 838, in save_base
    updated = self._save_table(raw, cls, force_insert, force_update, using, update_fields)
  File "/home/deeplearning/djangogirls/myvenv/lib/python3.5/site-packages/django/db/models/base.py", line 924, in _save_table
    result = self._do_insert(cls._base_manager, using, fields, update_pk, raw)
  File "/home/deeplearning/djangogirls/myvenv/lib/python3.5/site-packages/django/db/models/base.py", line 963, in _do_insert
    using=using, raw=raw)
  File "/home/deeplearning/djangogirls/myvenv/lib/python3.5/site-packages/django/db/models/manager.py", line 85, in manager_method
    return getattr(self.get_queryset(), name)(*args, **kwargs)
  File "/home/deeplearning/djangogirls/myvenv/lib/python3.5/site-packages/django/db/models/query.py", line 1076, in _insert
    return query.get_compiler(using=using).execute_sql(return_id)
  File "/home/deeplearning/djangogirls/myvenv/lib/python3.5/site-packages/django/db/models/sql/compiler.py", line 1112, in execute_sql
    cursor.execute(sql, params)
  File "/home/deeplearning/djangogirls/myvenv/lib/python3.5/site-packages/django/db/backends/utils.py", line 79, in execute
    return super(CursorDebugWrapper, self).execute(sql, params)
  File "/home/deeplearning/djangogirls/myvenv/lib/python3.5/site-packages/django/db/backends/utils.py", line 64, in execute
    return self.cursor.execute(sql, params)
  File "/home/deeplearning/djangogirls/myvenv/lib/python3.5/site-packages/django/db/utils.py", line 94, in __exit__
    six.reraise(dj_exc_type, dj_exc_value, traceback)
  File "/home/deeplearning/djangogirls/myvenv/lib/python3.5/site-packages/django/utils/six.py", line 685, in reraise
    raise value.with_traceback(tb)
  File "/home/deeplearning/djangogirls/myvenv/lib/python3.5/site-packages/django/db/backends/utils.py", line 64, in execute
    return self.cursor.execute(sql, params)
  File "/home/deeplearning/djangogirls/myvenv/lib/python3.5/site-packages/django/db/backends/sqlite3/base.py", line 328, in execute
    return Database.Cursor.execute(self, query, params)
django.db.utils.OperationalError: no such table: blog_instabotdjangomodel
ERROR:django.request:Internal Server Error: /admin/blog/instabotdjangomodel/add/
Traceback (most recent call last):
  File "/home/deeplearning/djangogirls/myvenv/lib/python3.5/site-packages/django/db/backends/utils.py", line 64, in execute
    return self.cursor.execute(sql, params)
  File "/home/deeplearning/djangogirls/myvenv/lib/python3.5/site-packages/django/db/backends/sqlite3/base.py", line 328, in execute
    return Database.Cursor.execute(self, query, params)
sqlite3.OperationalError: no such table: blog_instabotdjangomodel

The above exception was the direct cause of the following exception:

Traceback (most recent call last):
  File "/home/deeplearning/djangogirls/myvenv/lib/python3.5/site-packages/django/core/handlers/exception.py", line 41, in inner
    response = get_response(request)
  File "/home/deeplearning/djangogirls/myvenv/lib/python3.5/site-packages/django/core/handlers/base.py", line 187, in _get_response
    response = self.process_exception_by_middleware(e, request)
  File "/home/deeplearning/djangogirls/myvenv/lib/python3.5/site-packages/django/core/handlers/base.py", line 185, in _get_response
    response = wrapped_callback(request, *callback_args, **callback_kwargs)
  File "/home/deeplearning/djangogirls/myvenv/lib/python3.5/site-packages/django/contrib/admin/options.py", line 551, in wrapper
    return self.admin_site.admin_view(view)(*args, **kwargs)
  File "/home/deeplearning/djangogirls/myvenv/lib/python3.5/site-packages/django/utils/decorators.py", line 149, in _wrapped_view
    response = view_func(request, *args, **kwargs)
  File "/home/deeplearning/djangogirls/myvenv/lib/python3.5/site-packages/django/views/decorators/cache.py", line 57, in _wrapped_view_func
    response = view_func(request, *args, **kwargs)
  File "/home/deeplearning/djangogirls/myvenv/lib/python3.5/site-packages/django/contrib/admin/sites.py", line 224, in inner
    return view(request, *args, **kwargs)
  File "/home/deeplearning/djangogirls/myvenv/lib/python3.5/site-packages/django/contrib/admin/options.py", line 1508, in add_view
    return self.changeform_view(request, None, form_url, extra_context)
  File "/home/deeplearning/djangogirls/myvenv/lib/python3.5/site-packages/django/utils/decorators.py", line 67, in _wrapper
    return bound_func(*args, **kwargs)
  File "/home/deeplearning/djangogirls/myvenv/lib/python3.5/site-packages/django/utils/decorators.py", line 149, in _wrapped_view
    response = view_func(request, *args, **kwargs)
  File "/home/deeplearning/djangogirls/myvenv/lib/python3.5/site-packages/django/utils/decorators.py", line 63, in bound_func
    return func.__get__(self, type(self))(*args2, **kwargs2)
  File "/home/deeplearning/djangogirls/myvenv/lib/python3.5/site-packages/django/contrib/admin/options.py", line 1408, in changeform_view
    return self._changeform_view(request, object_id, form_url, extra_context)
  File "/home/deeplearning/djangogirls/myvenv/lib/python3.5/site-packages/django/contrib/admin/options.py", line 1448, in _changeform_view
    self.save_model(request, new_object, form, not add)
  File "/home/deeplearning/djangogirls/myvenv/lib/python3.5/site-packages/django/contrib/admin/options.py", line 979, in save_model
    obj.save()
  File "/home/deeplearning/djangogirls/myvenv/lib/python3.5/site-packages/django/db/models/base.py", line 808, in save
    force_update=force_update, update_fields=update_fields)
  File "/home/deeplearning/djangogirls/myvenv/lib/python3.5/site-packages/django/db/models/base.py", line 838, in save_base
    updated = self._save_table(raw, cls, force_insert, force_update, using, update_fields)
  File "/home/deeplearning/djangogirls/myvenv/lib/python3.5/site-packages/django/db/models/base.py", line 924, in _save_table
    result = self._do_insert(cls._base_manager, using, fields, update_pk, raw)
  File "/home/deeplearning/djangogirls/myvenv/lib/python3.5/site-packages/django/db/models/base.py", line 963, in _do_insert
    using=using, raw=raw)
  File "/home/deeplearning/djangogirls/myvenv/lib/python3.5/site-packages/django/db/models/manager.py", line 85, in manager_method
    return getattr(self.get_queryset(), name)(*args, **kwargs)
  File "/home/deeplearning/djangogirls/myvenv/lib/python3.5/site-packages/django/db/models/query.py", line 1076, in _insert
    return query.get_compiler(using=using).execute_sql(return_id)
  File "/home/deeplearning/djangogirls/myvenv/lib/python3.5/site-packages/django/db/models/sql/compiler.py", line 1112, in execute_sql
    cursor.execute(sql, params)
  File "/home/deeplearning/djangogirls/myvenv/lib/python3.5/site-packages/django/db/backends/utils.py", line 79, in execute
    return super(CursorDebugWrapper, self).execute(sql, params)
  File "/home/deeplearning/djangogirls/myvenv/lib/python3.5/site-packages/django/db/backends/utils.py", line 64, in execute
    return self.cursor.execute(sql, params)
  File "/home/deeplearning/djangogirls/myvenv/lib/python3.5/site-packages/django/db/utils.py", line 94, in __exit__
    six.reraise(dj_exc_type, dj_exc_value, traceback)
  File "/home/deeplearning/djangogirls/myvenv/lib/python3.5/site-packages/django/utils/six.py", line 685, in reraise
    raise value.with_traceback(tb)
  File "/home/deeplearning/djangogirls/myvenv/lib/python3.5/site-packages/django/db/backends/utils.py", line 64, in execute
    return self.cursor.execute(sql, params)
  File "/home/deeplearning/djangogirls/myvenv/lib/python3.5/site-packages/django/db/backends/sqlite3/base.py", line 328, in execute
    return Database.Cursor.execute(self, query, params)
django.db.utils.OperationalError: no such table: blog_instabotdjangomodel
ERROR:django.request:Internal Server Error: /
Traceback (most recent call last):
  File "/home/deeplearning/djangogirls/myvenv/lib/python3.5/site-packages/django/core/handlers/exception.py", line 41, in inner
    response = get_response(request)
  File "/home/deeplearning/djangogirls/myvenv/lib/python3.5/site-packages/django/core/handlers/base.py", line 187, in _get_response
    response = self.process_exception_by_middleware(e, request)
  File "/home/deeplearning/djangogirls/myvenv/lib/python3.5/site-packages/django/core/handlers/base.py", line 185, in _get_response
    response = wrapped_callback(request, *callback_args, **callback_kwargs)
  File "/home/deeplearning/djangogirls/blog/views.py", line 12, in post_list
    posts = PostInstabotDjangoModel.objects.all()
AttributeError: type object 'PostInstabotDjangoModel' has no attribute 'objects'
ERROR:django.request:Internal Server Error: /
Traceback (most recent call last):
  File "/home/deeplearning/djangogirls/myvenv/lib/python3.5/site-packages/django/core/handlers/exception.py", line 41, in inner
    response = get_response(request)
  File "/home/deeplearning/djangogirls/myvenv/lib/python3.5/site-packages/django/core/handlers/base.py", line 187, in _get_response
    response = self.process_exception_by_middleware(e, request)
  File "/home/deeplearning/djangogirls/myvenv/lib/python3.5/site-packages/django/core/handlers/base.py", line 185, in _get_response
    response = wrapped_callback(request, *callback_args, **callback_kwargs)
  File "/home/deeplearning/djangogirls/blog/views.py", line 12, in post_list
    posts = PostInstabotDjangoModel.all()
AttributeError: type object 'PostInstabotDjangoModel' has no attribute 'all'
ERROR:django.request:Internal Server Error: /
Traceback (most recent call last):
  File "/home/deeplearning/djangogirls/myvenv/lib/python3.5/site-packages/django/core/handlers/exception.py", line 41, in inner
    response = get_response(request)
  File "/home/deeplearning/djangogirls/myvenv/lib/python3.5/site-packages/django/core/handlers/base.py", line 187, in _get_response
    response = self.process_exception_by_middleware(e, request)
  File "/home/deeplearning/djangogirls/myvenv/lib/python3.5/site-packages/django/core/handlers/base.py", line 185, in _get_response
    response = wrapped_callback(request, *callback_args, **callback_kwargs)
  File "/home/deeplearning/djangogirls/blog/views.py", line 12, in post_list
    posts = PostInstabotDjangoModel.all()
AttributeError: type object 'PostInstabotDjangoModel' has no attribute 'all'
ERROR:django.request:Internal Server Error: /
Traceback (most recent call last):
  File "/home/deeplearning/djangogirls/myvenv/lib/python3.5/site-packages/django/core/handlers/exception.py", line 41, in inner
    response = get_response(request)
  File "/home/deeplearning/djangogirls/myvenv/lib/python3.5/site-packages/django/core/handlers/base.py", line 187, in _get_response
    response = self.process_exception_by_middleware(e, request)
  File "/home/deeplearning/djangogirls/myvenv/lib/python3.5/site-packages/django/core/handlers/base.py", line 185, in _get_response
    response = wrapped_callback(request, *callback_args, **callback_kwargs)
  File "/home/deeplearning/djangogirls/blog/views.py", line 12, in post_list
    posts = PostInstabotDjangoModel.objects.all()
AttributeError: type object 'PostInstabotDjangoModel' has no attribute 'objects'
ERROR:django.request:Internal Server Error: /
Traceback (most recent call last):
  File "/home/deeplearning/djangogirls/myvenv/lib/python3.5/site-packages/django/db/backends/utils.py", line 64, in execute
    return self.cursor.execute(sql, params)
  File "/home/deeplearning/djangogirls/myvenv/lib/python3.5/site-packages/django/db/backends/sqlite3/base.py", line 328, in execute
    return Database.Cursor.execute(self, query, params)
sqlite3.OperationalError: no such column: blog_instabotdjangomodel.title

The above exception was the direct cause of the following exception:

Traceback (most recent call last):
  File "/home/deeplearning/djangogirls/myvenv/lib/python3.5/site-packages/django/core/handlers/exception.py", line 41, in inner
    response = get_response(request)
  File "/home/deeplearning/djangogirls/myvenv/lib/python3.5/site-packages/django/core/handlers/base.py", line 187, in _get_response
    response = self.process_exception_by_middleware(e, request)
  File "/home/deeplearning/djangogirls/myvenv/lib/python3.5/site-packages/django/core/handlers/base.py", line 185, in _get_response
    response = wrapped_callback(request, *callback_args, **callback_kwargs)
  File "/home/deeplearning/djangogirls/blog/views.py", line 13, in post_list
    return render(request, 'blog/post_list.html', {'posts': posts})
  File "/home/deeplearning/djangogirls/myvenv/lib/python3.5/site-packages/django/shortcuts.py", line 30, in render
    content = loader.render_to_string(template_name, context, request, using=using)
  File "/home/deeplearning/djangogirls/myvenv/lib/python3.5/site-packages/django/template/loader.py", line 68, in render_to_string
    return template.render(context, request)
  File "/home/deeplearning/djangogirls/myvenv/lib/python3.5/site-packages/django/template/backends/django.py", line 66, in render
    return self.template.render(context)
  File "/home/deeplearning/djangogirls/myvenv/lib/python3.5/site-packages/django/template/base.py", line 207, in render
    return self._render(context)
  File "/home/deeplearning/djangogirls/myvenv/lib/python3.5/site-packages/django/template/base.py", line 199, in _render
    return self.nodelist.render(context)
  File "/home/deeplearning/djangogirls/myvenv/lib/python3.5/site-packages/django/template/base.py", line 990, in render
    bit = node.render_annotated(context)
  File "/home/deeplearning/djangogirls/myvenv/lib/python3.5/site-packages/django/template/base.py", line 957, in render_annotated
    return self.render(context)
  File "/home/deeplearning/djangogirls/myvenv/lib/python3.5/site-packages/django/template/loader_tags.py", line 177, in render
    return compiled_parent._render(context)
  File "/home/deeplearning/djangogirls/myvenv/lib/python3.5/site-packages/django/template/base.py", line 199, in _render
    return self.nodelist.render(context)
  File "/home/deeplearning/djangogirls/myvenv/lib/python3.5/site-packages/django/template/base.py", line 990, in render
    bit = node.render_annotated(context)
  File "/home/deeplearning/djangogirls/myvenv/lib/python3.5/site-packages/django/template/base.py", line 957, in render_annotated
    return self.render(context)
  File "/home/deeplearning/djangogirls/myvenv/lib/python3.5/site-packages/django/template/loader_tags.py", line 72, in render
    result = block.nodelist.render(context)
  File "/home/deeplearning/djangogirls/myvenv/lib/python3.5/site-packages/django/template/base.py", line 990, in render
    bit = node.render_annotated(context)
  File "/home/deeplearning/djangogirls/myvenv/lib/python3.5/site-packages/django/template/base.py", line 957, in render_annotated
    return self.render(context)
  File "/home/deeplearning/djangogirls/myvenv/lib/python3.5/site-packages/django/template/defaulttags.py", line 173, in render
    len_values = len(values)
  File "/home/deeplearning/djangogirls/myvenv/lib/python3.5/site-packages/django/db/models/query.py", line 232, in __len__
    self._fetch_all()
  File "/home/deeplearning/djangogirls/myvenv/lib/python3.5/site-packages/django/db/models/query.py", line 1118, in _fetch_all
    self._result_cache = list(self._iterable_class(self))
  File "/home/deeplearning/djangogirls/myvenv/lib/python3.5/site-packages/django/db/models/query.py", line 53, in __iter__
    results = compiler.execute_sql(chunked_fetch=self.chunked_fetch)
  File "/home/deeplearning/djangogirls/myvenv/lib/python3.5/site-packages/django/db/models/sql/compiler.py", line 899, in execute_sql
    raise original_exception
  File "/home/deeplearning/djangogirls/myvenv/lib/python3.5/site-packages/django/db/models/sql/compiler.py", line 889, in execute_sql
    cursor.execute(sql, params)
  File "/home/deeplearning/djangogirls/myvenv/lib/python3.5/site-packages/django/db/backends/utils.py", line 79, in execute
    return super(CursorDebugWrapper, self).execute(sql, params)
  File "/home/deeplearning/djangogirls/myvenv/lib/python3.5/site-packages/django/db/backends/utils.py", line 64, in execute
    return self.cursor.execute(sql, params)
  File "/home/deeplearning/djangogirls/myvenv/lib/python3.5/site-packages/django/db/utils.py", line 94, in __exit__
    six.reraise(dj_exc_type, dj_exc_value, traceback)
  File "/home/deeplearning/djangogirls/myvenv/lib/python3.5/site-packages/django/utils/six.py", line 685, in reraise
    raise value.with_traceback(tb)
  File "/home/deeplearning/djangogirls/myvenv/lib/python3.5/site-packages/django/db/backends/utils.py", line 64, in execute
    return self.cursor.execute(sql, params)
  File "/home/deeplearning/djangogirls/myvenv/lib/python3.5/site-packages/django/db/backends/sqlite3/base.py", line 328, in execute
    return Database.Cursor.execute(self, query, params)
django.db.utils.OperationalError: no such column: blog_instabotdjangomodel.title
ERROR:django.request:Internal Server Error: /
Traceback (most recent call last):
  File "/home/deeplearning/djangogirls/myvenv/lib/python3.5/site-packages/django/db/backends/utils.py", line 64, in execute
    return self.cursor.execute(sql, params)
  File "/home/deeplearning/djangogirls/myvenv/lib/python3.5/site-packages/django/db/backends/sqlite3/base.py", line 328, in execute
    return Database.Cursor.execute(self, query, params)
sqlite3.OperationalError: no such column: blog_instabotdjangomodel.title

The above exception was the direct cause of the following exception:

Traceback (most recent call last):
  File "/home/deeplearning/djangogirls/myvenv/lib/python3.5/site-packages/django/core/handlers/exception.py", line 41, in inner
    response = get_response(request)
  File "/home/deeplearning/djangogirls/myvenv/lib/python3.5/site-packages/django/core/handlers/base.py", line 187, in _get_response
    response = self.process_exception_by_middleware(e, request)
  File "/home/deeplearning/djangogirls/myvenv/lib/python3.5/site-packages/django/core/handlers/base.py", line 185, in _get_response
    response = wrapped_callback(request, *callback_args, **callback_kwargs)
  File "/home/deeplearning/djangogirls/blog/views.py", line 13, in post_list
    return render(request, 'blog/post_list.html', {'posts': posts})
  File "/home/deeplearning/djangogirls/myvenv/lib/python3.5/site-packages/django/shortcuts.py", line 30, in render
    content = loader.render_to_string(template_name, context, request, using=using)
  File "/home/deeplearning/djangogirls/myvenv/lib/python3.5/site-packages/django/template/loader.py", line 68, in render_to_string
    return template.render(context, request)
  File "/home/deeplearning/djangogirls/myvenv/lib/python3.5/site-packages/django/template/backends/django.py", line 66, in render
    return self.template.render(context)
  File "/home/deeplearning/djangogirls/myvenv/lib/python3.5/site-packages/django/template/base.py", line 207, in render
    return self._render(context)
  File "/home/deeplearning/djangogirls/myvenv/lib/python3.5/site-packages/django/template/base.py", line 199, in _render
    return self.nodelist.render(context)
  File "/home/deeplearning/djangogirls/myvenv/lib/python3.5/site-packages/django/template/base.py", line 990, in render
    bit = node.render_annotated(context)
  File "/home/deeplearning/djangogirls/myvenv/lib/python3.5/site-packages/django/template/base.py", line 957, in render_annotated
    return self.render(context)
  File "/home/deeplearning/djangogirls/myvenv/lib/python3.5/site-packages/django/template/loader_tags.py", line 177, in render
    return compiled_parent._render(context)
  File "/home/deeplearning/djangogirls/myvenv/lib/python3.5/site-packages/django/template/base.py", line 199, in _render
    return self.nodelist.render(context)
  File "/home/deeplearning/djangogirls/myvenv/lib/python3.5/site-packages/django/template/base.py", line 990, in render
    bit = node.render_annotated(context)
  File "/home/deeplearning/djangogirls/myvenv/lib/python3.5/site-packages/django/template/base.py", line 957, in render_annotated
    return self.render(context)
  File "/home/deeplearning/djangogirls/myvenv/lib/python3.5/site-packages/django/template/loader_tags.py", line 72, in render
    result = block.nodelist.render(context)
  File "/home/deeplearning/djangogirls/myvenv/lib/python3.5/site-packages/django/template/base.py", line 990, in render
    bit = node.render_annotated(context)
  File "/home/deeplearning/djangogirls/myvenv/lib/python3.5/site-packages/django/template/base.py", line 957, in render_annotated
    return self.render(context)
  File "/home/deeplearning/djangogirls/myvenv/lib/python3.5/site-packages/django/template/defaulttags.py", line 173, in render
    len_values = len(values)
  File "/home/deeplearning/djangogirls/myvenv/lib/python3.5/site-packages/django/db/models/query.py", line 232, in __len__
    self._fetch_all()
  File "/home/deeplearning/djangogirls/myvenv/lib/python3.5/site-packages/django/db/models/query.py", line 1118, in _fetch_all
    self._result_cache = list(self._iterable_class(self))
  File "/home/deeplearning/djangogirls/myvenv/lib/python3.5/site-packages/django/db/models/query.py", line 53, in __iter__
    results = compiler.execute_sql(chunked_fetch=self.chunked_fetch)
  File "/home/deeplearning/djangogirls/myvenv/lib/python3.5/site-packages/django/db/models/sql/compiler.py", line 899, in execute_sql
    raise original_exception
  File "/home/deeplearning/djangogirls/myvenv/lib/python3.5/site-packages/django/db/models/sql/compiler.py", line 889, in execute_sql
    cursor.execute(sql, params)
  File "/home/deeplearning/djangogirls/myvenv/lib/python3.5/site-packages/django/db/backends/utils.py", line 79, in execute
    return super(CursorDebugWrapper, self).execute(sql, params)
  File "/home/deeplearning/djangogirls/myvenv/lib/python3.5/site-packages/django/db/backends/utils.py", line 64, in execute
    return self.cursor.execute(sql, params)
  File "/home/deeplearning/djangogirls/myvenv/lib/python3.5/site-packages/django/db/utils.py", line 94, in __exit__
    six.reraise(dj_exc_type, dj_exc_value, traceback)
  File "/home/deeplearning/djangogirls/myvenv/lib/python3.5/site-packages/django/utils/six.py", line 685, in reraise
    raise value.with_traceback(tb)
  File "/home/deeplearning/djangogirls/myvenv/lib/python3.5/site-packages/django/db/backends/utils.py", line 64, in execute
    return self.cursor.execute(sql, params)
  File "/home/deeplearning/djangogirls/myvenv/lib/python3.5/site-packages/django/db/backends/sqlite3/base.py", line 328, in execute
    return Database.Cursor.execute(self, query, params)
django.db.utils.OperationalError: no such column: blog_instabotdjangomodel.title
ERROR:django.request:Internal Server Error: /post/new/
Traceback (most recent call last):
  File "/home/deeplearning/djangogirls/myvenv/lib/python3.5/site-packages/django/core/handlers/exception.py", line 41, in inner
    response = get_response(request)
  File "/home/deeplearning/djangogirls/myvenv/lib/python3.5/site-packages/django/core/handlers/base.py", line 187, in _get_response
    response = self.process_exception_by_middleware(e, request)
  File "/home/deeplearning/djangogirls/myvenv/lib/python3.5/site-packages/django/core/handlers/base.py", line 185, in _get_response
    response = wrapped_callback(request, *callback_args, **callback_kwargs)
  File "/home/deeplearning/djangogirls/blog/views.py", line 79, in post_new
    unfollow_whitelist=['example_user_1', 'example_user_2'])
  File "/home/deeplearning/djangogirls/blog/src/instabot.py", line 233, in __init__
    signal.signal(signal.SIGTERM, self.cleanup)
  File "/usr/lib/python3.5/signal.py", line 47, in signal
    handler = _signal.signal(_enum_to_int(signalnum), _enum_to_int(handler))
ValueError: signal only works in main thread
